2020-03-19 00:36:01,961 ERROR: Exception on /login [GET] [in e:\flask_project\venv\lib\site-packages\flask\app.py:1891]
Traceback (most recent call last):
  File "e:\flask_project\venv\lib\site-packages\flask\app.py", line 2446, in wsgi_app
    response = self.full_dispatch_request()
  File "e:\flask_project\venv\lib\site-packages\flask\app.py", line 1951, in full_dispatch_request
    rv = self.handle_user_exception(e)
  File "e:\flask_project\venv\lib\site-packages\flask\app.py", line 1820, in handle_user_exception
    reraise(exc_type, exc_value, tb)
  File "e:\flask_project\venv\lib\site-packages\flask\_compat.py", line 39, in reraise
    raise value
  File "e:\flask_project\venv\lib\site-packages\flask\app.py", line 1949, in full_dispatch_request
    rv = self.dispatch_request()
  File "e:\flask_project\venv\lib\site-packages\flask\app.py", line 1935, in dispatch_request
    return self.view_functions[rule.endpoint](**req.view_args)
  File "E:\Flask_Project\app\routes.py", line 42, in login
    return render_template('login.html',title='Sign In',form=form)
  File "e:\flask_project\venv\lib\site-packages\flask\templating.py", line 140, in render_template
    ctx.app,
  File "e:\flask_project\venv\lib\site-packages\flask\templating.py", line 120, in _render
    rv = template.render(context)
  File "e:\flask_project\venv\lib\site-packages\jinja2\environment.py", line 1090, in render
    self.environment.handle_exception()
  File "e:\flask_project\venv\lib\site-packages\jinja2\environment.py", line 832, in handle_exception
    reraise(*rewrite_traceback_stack(source=source))
  File "e:\flask_project\venv\lib\site-packages\jinja2\_compat.py", line 28, in reraise
    raise value.with_traceback(tb)
  File "E:\Flask_Project\app\templates\login.html", line 1, in top-level template code
    {% extends "base.html" %}
  File "E:\Flask_Project\app\templates\base.html", line 19, in top-level template code
    <a href="{{ url_for('explore') }}">Explore</a>
  File "e:\flask_project\venv\lib\site-packages\flask\helpers.py", line 370, in url_for
    return appctx.app.handle_url_build_error(error, endpoint, values)
  File "e:\flask_project\venv\lib\site-packages\flask\app.py", line 2215, in handle_url_build_error
    reraise(exc_type, exc_value, tb)
  File "e:\flask_project\venv\lib\site-packages\flask\_compat.py", line 39, in reraise
    raise value
  File "e:\flask_project\venv\lib\site-packages\flask\helpers.py", line 358, in url_for
    endpoint, values, method=method, force_external=external
  File "e:\flask_project\venv\lib\site-packages\werkzeug\routing.py", line 2179, in build
    raise BuildError(endpoint, values, method, self)
werkzeug.routing.BuildError: Could not build url for endpoint 'explore'. Did you mean 'edit_profile' instead?
2020-03-19 00:36:02,797 ERROR: Exception on /favicon.ico [GET] [in e:\flask_project\venv\lib\site-packages\flask\app.py:1891]
Traceback (most recent call last):
  File "e:\flask_project\venv\lib\site-packages\flask\app.py", line 1949, in full_dispatch_request
    rv = self.dispatch_request()
  File "e:\flask_project\venv\lib\site-packages\flask\app.py", line 1925, in dispatch_request
    self.raise_routing_exception(req)
  File "e:\flask_project\venv\lib\site-packages\flask\app.py", line 1907, in raise_routing_exception
    raise request.routing_exception
  File "e:\flask_project\venv\lib\site-packages\flask\ctx.py", line 350, in match_request
    result = self.url_adapter.match(return_rule=True)
  File "e:\flask_project\venv\lib\site-packages\werkzeug\routing.py", line 1945, in match
    raise NotFound()
werkzeug.exceptions.NotFound: 404 Not Found: The requested URL was not found on the server. If you entered the URL manually please check your spelling and try again.

During handling of the above exception, another exception occurred:

Traceback (most recent call last):
  File "e:\flask_project\venv\lib\site-packages\flask\app.py", line 2446, in wsgi_app
    response = self.full_dispatch_request()
  File "e:\flask_project\venv\lib\site-packages\flask\app.py", line 1951, in full_dispatch_request
    rv = self.handle_user_exception(e)
  File "e:\flask_project\venv\lib\site-packages\flask\app.py", line 1815, in handle_user_exception
    return self.handle_http_exception(e)
  File "e:\flask_project\venv\lib\site-packages\flask\app.py", line 1743, in handle_http_exception
    return handler(e)
  File "E:\Flask_Project\app\errors.py", line 7, in not_found_error
    return render_template('404.html'),404
  File "e:\flask_project\venv\lib\site-packages\flask\templating.py", line 140, in render_template
    ctx.app,
  File "e:\flask_project\venv\lib\site-packages\flask\templating.py", line 120, in _render
    rv = template.render(context)
  File "e:\flask_project\venv\lib\site-packages\jinja2\environment.py", line 1090, in render
    self.environment.handle_exception()
  File "e:\flask_project\venv\lib\site-packages\jinja2\environment.py", line 832, in handle_exception
    reraise(*rewrite_traceback_stack(source=source))
  File "e:\flask_project\venv\lib\site-packages\jinja2\_compat.py", line 28, in reraise
    raise value.with_traceback(tb)
  File "E:\Flask_Project\app\templates\404.html", line 1, in top-level template code
    {% extends "base.html" %}
  File "E:\Flask_Project\app\templates\base.html", line 19, in top-level template code
    <a href="{{ url_for('explore') }}">Explore</a>
  File "e:\flask_project\venv\lib\site-packages\flask\helpers.py", line 370, in url_for
    return appctx.app.handle_url_build_error(error, endpoint, values)
  File "e:\flask_project\venv\lib\site-packages\flask\app.py", line 2215, in handle_url_build_error
    reraise(exc_type, exc_value, tb)
  File "e:\flask_project\venv\lib\site-packages\flask\_compat.py", line 39, in reraise
    raise value
  File "e:\flask_project\venv\lib\site-packages\flask\helpers.py", line 358, in url_for
    endpoint, values, method=method, force_external=external
  File "e:\flask_project\venv\lib\site-packages\werkzeug\routing.py", line 2179, in build
    raise BuildError(endpoint, values, method, self)
werkzeug.routing.BuildError: Could not build url for endpoint 'explore'. Did you mean 'edit_profile' instead?
2020-03-19 12:28:28,304 INFO: Microblog startup [in E:\Flask_Project\app\__init__.py:46]
